Workbook

Sheet mainfort-data-collapsed
A1: site_name | B1: Parkin_Punctated | C1: Barton/Kent/MPI | D1: ranch_inc | E1: painted | F1: rhodes_inc | G1: walls_eng | H1: vernon_pal | I1: fortune_nd
A2: Porter | B2: 137 | C2: 14 | D2: 1 | E2: 91 | F2: 0 | G2: 4 | H2: 1 | I2: 7
A3: 40LA007 | B3: 43 | C3: 4 | D3: 0 | E3: 39 | F3: 0 | G3: 0 | H3: 0 | I3: 0
A4: Hatchie | B4: 64 | C4: 10 | D4: 4 | E4: 10 | F4: 0 | G4: 0 | H4: 1 | I4: 1
A5: Bishop | B5: 18 | C5: 3 | D5: 0 | E5: 10 | F5: 2 | G5: 1 | H5: 0 | I5: 0
A6: Richardsons_Landing | B6: 16 | C6: 13 | D6: 1 | E6: 27 | F6: 1 | G6: 3 | H6: 0 | I6: 0
A7: Wilder | B7: 68 | C7: 19 | D7: 6 | E7: 30 | F7: 2 | G7: 3 | H7: 0 | I7: 0
A8: 40TP026 | B8: 6 | C8: 3 | D8: 4 | E8: 20 | F8: 0 | G8: 0 | H8: 0 | I8: 0
A9: Jones_Bayou | B9: 174 | C9: 3 | D9: 2 | E9: 159 | F9: 0 | G9: 2 | H9: 2 | I9: 0
A10: Fullen | B10: 66 | C10: 11 | D10: 0 | E10: 76 | F10: 0 | G10: 2 | H10: 0 | I10: 0
A11: Jeter | B11: 70 | C11: 10 | D11: 1 | E11: 12 | F11: 1 | G11: 4 | H11: 0 | I11: 1
A12: Rast | B12: 122 | C12: 4 | D12: 2 | E12: 14 | F12: 3 | G12: 6 | H12: 0 | I12: 2
A13: Norfolk | B13: 36 | C13: 14 | D13: 6 | E13: 0 | F13: 1 | G13: 5 | H13: 0 | I13: 0
... A55: Belle_Meade | B55: 1522 | C55: 676 | D55: 36 | E55: 116 | F55: 17 | G55: 25 | H55: 2 | I55: 6

Sheet cpl-pfg
A1: Assemblages | B1: Parkin_Punctated | C1: Barton/Kent/MPI | D1: Painted | E1: Fortune_Noded | F1: Ranch_Incised | G1: Walls_Engraved | H1: Wallace_Incised | I1: Rhodes_Incised | J1: Vernon_Paul_Applique | K1: Hull_Engraved
A2: 10-P-1 | B2: 39 | C2: 62 | D2: 46 | E2: 0 | F2: 0 | G2: 0 | H2: 0 | I2: 0 | J2: 0 | K2: 6
A3: 11-N-9 | B3: 528 | C3: 198 | D3: 13 | E3: 0 | F3: 19 | G3: 0 | H3: 0 | I3: 0 | J3: 0 | K3: 0
A4: 11-N-1 | B4: 865 | C4: 323 | D4: 59 | E4: 17 | F4: 35 | G4: 0 | H4: 0 | I4: 0 | J4: 4 | K4: 0
A5: 11-O-10 | B5: 404 | C5: 208 | D5: 6 | E5: 16 | F5: 4 | G5: 0 | H5: 0 | I5: 0 | J5: 0 | K5: 0
A6: 11-N-4 | B6: 764 | C6: 470 | D6: 18 | E6: 5 | F6: 9 | G6: 0 | H6: 0 | I6: 0 | J6: 0 | K6: 0
A7: 13-N-5 | B7: 35 | C7: 11 | D7: 33 | E7: 0 | F7: 0 | G7: 0 | H7: 0 | I7: 0 | J7: 0 | K7: 0
A8: 13-N-4 | B8: 71 | C8: 67 | D8: 96 | E8: 0 | F8: 3 | G8: 4 | H8: 0 | I8: 0 | J8: 0 | K8: 0
A9: 13-N-16 | B9: 42 | C9: 56 | D9: 69 | E9: 0 | F9: 1 | G9: 3 | H9: 0 | I9: 0 | J9: 0 | K9: 0
A10: 13-O-11 | B10: 35 | C10: 65 | D10: 24 | E10: 0 | F10: 0 | G10: 2 | H10: 0 | I10: 1 | J10: 0 | K10: 1
A11: 13-O-10 | B11: 61 | C11: 74 | D11: 79 | E11: 0 | F11: 2 | G11: 8 | H11: 0 | I11: 2 | J11: 0 | K11: 0
A12: 13-P-1 | B12: 244 | C12: 40 | D12: 18 | E12: 1 | F12: 16 | G12: 21 | H12: 0 | I12: 14 | J12: 0 | K12: 6
A13: 13-P-8 | B13: 83 | C13: 25 | D13: 43 | E13: 0 | F13: 18 | G13: 17 | H13: 0 | I13: 3 | J13: 0 | K13: 3
... A21: 12-N-3 | B21: 549 | C21: 328 | D21: 77 | E21: 19 | F21: 4 | G21: 0 | H21: 3 | I21: 1 | J21: 2 | K21: 0

Sheet pfg-cpl-mainfort
A1: Assemblages | B1: Parkin_Punctated | C1: Barton/Kent/MPI | D1: Painted | E1: Fortune_Noded | F1: Ranch_Incised | G1: Walls_Engraved | H1: Wallace_Incised | I1: Rhodes_Incised | J1: Vernon_Paul_Applique | K1: Hull_Engraved
A2: 40LA007 | B2: 43 | C2: 4 | D2: 39 | E2: 0 | F2: 0 | G2: 0 | H2: 0 | I2: 0 | J2: 0 | K2: 0
A3: 40TP026 | B3: 6 | C3: 3 | D3: 20 | E3: 0 | F3: 4 | G3: 0 | H3: 0 | I3: 0 | J3: 0 | K3: 0
A4: Barton_Ranch | B4: 1194 | C4: 415 | D4: 12 | E4: 32 | F4: 8 | G4: 0 | H4: 0 | I4: 0 | J4: 0 | K4: 0
A5: Beck | B5: 1052 | C5: 684 | D5: 168 | E5: 10 | F5: 27 | G5: 28 | H5: 12 | I5: 16 | J5: 8 | K5: 1
A6: Belle_Meade | B6: 2445 | C6: 1313 | D6: 158 | E6: 18 | F6: 69 | G6: 52 | H6: 15 | I6: 30 | J6: 7 | K6: 2
A7: Big_Eddy | B7: 96 | C7: 76 | D7: 100 | E7: 1 | F7: 0 | G7: 0 | H7: 0 | I7: 1 | J7: 0 | K7: 0
A8: Bishop | B8: 18 | C8: 3 | D8: 10 | E8: 0 | F8: 0 | G8: 1 | H8: 0 | I8: 2 | J8: 0 | K8: 0
A9: Carson_Lake | B9: 117 | C9: 117 | D9: 83 | E9: 0 | F9: 9 | G9: 0 | H9: 0 | I9: 0 | J9: 0 | K9: 6
A10: Castile_Landing | B10: 962 | C10: 113 | D10: 175 | E10: 7 | F10: 7 | G10: 0 | H10: 1 | I10: 8 | J10: 2 | K10: 0
A11: Cheatham | B11: 44 | C11: 7 | D11: 3 | E11: 0 | F11: 4 | G11: 1 | H11: 0 | I11: 4 | J11: 0 | K11: 0
A12: Chuccalissa | B12: 1740 | C12: 104 | D12: 60 | E12: 22 | F12: 49 | G12: 48 | H12: 0 | I12: 12 | J12: 0 | K12: 0
A13: Clay_Hill | B13: 380 | C13: 125 | D13: 166 | E13: 0 | F13: 0 | G13: 4 | H13: 0 | I13: 2 | J13: 0 | K13: 0
... A56: Young | B56: 416 | C56: 109 | D56: 12 | E56: 1 | F56: 23 | G56: 8 | H56: 0 | I56: 0 | J56: 0 | K56: 0

Sheet PFG
A1: Site Number | B1: Site Name | C1: State | D1: AMASDA # | E1: County | F1: Quad | G1: T/R/S | H1: UTM North | I1: UTM E | J1: Zone | K1: Location | L1: PFG Type | M1: Collector | N1: PFG Collection Date | O1: Record Type | P1: Bluff Creek Punctate | Q1: Tchefuncte Plain | R1: Tchefuncte Incised | S1: Tchefuncte Stamped | T1: Jaketown Simple Stamped | U1: Tammy Pinched | V1: Lake Borgne Incised | W1: Thomas Plain | X1: Bowie Plain | Y1: Blue Lake Cordmarked | Z1: Twin Lakes Fabric Impressed | AA1: Cormorant Cord-impressed | AB1: Twin Lakes Punctated | AC1: Crowder Punctated | AD1: Baytown Plain | AE1: Mulberry Creek Cord-marked | AF1: Wheeler Check Stamped | AG1: Withers Fabric-impressed | AH1: Indian Bay Stamped | AI1: Oxbow Incised | AJ1: Evansville Punctated | AK1: Yates Net Impressed | AL1: Marksville Stamped | AM1: Marksville Incised | AN1: Troyville Stamped | AO1: Churupa I ncised | AP1: Coles Creek Incised | AQ1: Mazique Incised | AR1: French Fork Incised | AS1: Woodville Red Filmed | AT1: Chevalier Stamped | AU1: L'Eau Noire Incised | AV1: Larto Red Filmed | AW1: Unclass C.T. Inc. & Punct. | AX1: Neeley's Ferry Plain | AY1: Parkin Punctated | AZ1: Parkin Incised | BA1: Ranch Incised | BB1: Vernon Paul Applique | BC1: Fortune Noded | BD1: Manly Punctated (T) | BE1: Tyronza Punctated (T) | BF1: Bell Plain | BG1: Kent Incised | BH1: Rhodes Incised | BI1: Walls Engraved | BJ1: Hull Engraved | BK1: Mound Place Incised (T) | BL1: Old Town Red | BM1: Carson Red-on-Buff | BN1: Nodena Red and White | BO1: Avenue Polychrome | BP1: Hollywood White Slipped | BQ1: Spendthrift Negative Painted | BR1: Wallace Incised | BS1: Owens Punctated (T) | BT1: Leland Incised | BU1: Blanchard Incised (T) | BV1: Arcola Incised (T) | BW1: Unclassified St. Inc and Punct. | BX1: Unclassified | BY1: Shell Tempered C.M. | BZ1: Sherd Total | CA1: Period (From PFG Seriations) | CB1: PFG Notes | CC1: Percent Decorated | CD1: Number of Plain Sherds | CE1: Number of Shell Tempered Sherds | CF1: Number of Decorated Shell Tempered Sherds | CG1: Percentage of Shell Tempered Decroated Ceramics | CH1: Area
A2: 10-P-1 | B2: Carson Lake | C2: AR | D2: 3MS0013 | E2: Mississippi | F2: 986 | G2: 11N/10E/ 5 | H2: 3943300 | I2: 767520 | J2: 15 | L2: Slightly elevated village site - no mounds | M2: Phillips | N2: 14723 | O2: map | T2: 0 | U2: 0 | V2: 0 | W2: 0 | Y2: 0 | Z2: 0 | AA2: 0 | AC2: 0 | AD2: 16 | AE2: 10 | AF2: 0 | AG2: 2 | AH2: 0 | AJ2: 0 | AL2: 0 | AM2: 0 | AN2: 0 | AP2: 0 | AQ2: 0 | AR2: 0 | AS2: 0 | AT2: 0 | AV2: 0 | AW2: 0 | AX2: 2753 | AY2: 39 | AZ2: 57 | BA2: 0 | BB2: 0 | BC2: 0 | BD2: 0 | BE2: 0 | BF2: 577 | BG2: 4 | BH2: 0 | BI2: 0 | BJ2: 6 | BK2: 1 | BL2: 22 | BM2: 0 | BN2: 0 | BO2: 24 | BR2: 0 | BS2: 6 | BT2: 0 | BV2: 0 | BZ2: =SUM(T2:BY2) -> 3517 | CA2: B | CB2: Part of this is quite late | CC2: =SUM(BG2:BV2,AE2:AW2,AY2:BE2,T2:AC2)/BZ2 -> 0.048620984 | CD2: =BZ2-SUM(BF2,AX2,AW2,AD2,W2) -> 171 | CE2: =SUM(AX2:BV2) -> 3489 | CF2: =SUM(BG2:BV2,AY2:BE2) -> 159 | CG2: =CF2/CE2 -> 0.045571797 | CH2: Memphis
A3: 10-P-2 | B3: Bell | C3: AR | D3: 3MS0008 | E3: Mississip | F3: 986 | G3: 11N/09/34 | H3: 3935520 | I3: 761580 | J3: 15 | L3: Famous burial site- village site indications not conspicuous | M3: Phillips | N3: 14724 | O3: map | T3: 0 | U3: 0 | V3: 0 | W3: 0 | Y3: 0 | Z3: 0 | AA3: 0 | AC3: 0 | AD3: 1 | AE3: 0 | AF3: 0 | AG3: 0 | AH3: 0 | AJ3: 0 | AL3: 0 | AM3: 0 | AN3: 0 | AP3: 0 | AQ3: 0 | AR3: 0 | AS3: 0 | AT3: 0 | AV3: 0 | AW3: 0 | AX3: 211 | AY3: 0 | AZ3: 6 | BA3: 0 | BB3: 0 | BC3: 0 | BD3: 1 | BE3: 0 | BF3: 117 | BG3: 2 | BH3: 0 | BI3: 0 | BJ3: 0 | BK3: 0 | BL3: 5 | BM3: 0 | BN3: 0 | BO3: 0 | BR3: 0 | BS3: 0 | BT3: 0 | BV3: 0 | BZ3: =SUM(T3:BY3) -> 343 | CA3: A | CC3: =SUM(BG3:BV3,AE3:AW3,AY3:BE3,T3:AC3)/BZ3 -> 0.040816327 | CD3: =BZ3-SUM(BF3,AX3,AW3,AD3,W3) -> 14 | CE3: =SUM(AX3:BV3) -> 342 | CF3: =SUM(BG3:BV3,AY3:BE3) -> 14 | CG3: =CF3/CE3 -> 0.040935673 | CH3: Memphis
A4: 10-P-3 | B4: Nettle Ridge | C4: AR | D4: 3MS00014 | E4: Mississip | F4: 229 | G4: 10N/09E/4 | H4: 3934120 | I4: 760410 | J4: 15 | L4: Large village site - no mounds | M4: Phillips | N4: 14723 | O4: map | T4: 0 | U4: 0 | V4: 0 | W4: 0 | Y4: 0 | Z4: 0 | AA4: 0 | AC4: 0 | AD4: 49 | AE4: 97 | AF4: 22 | AG4: 2 | AH4: 0 | AJ4: 0 | AL4: 0 | AM4: 0 | AN4: 0 | AP4: 0 | AQ4: 0 | AR4: 0 | AS4: 0 | AT4: 0 | AV4: 0 | AW4: 0 | AX4: 155 | AY4: 9 | AZ4: 1 | BA4: 0 | BB4: 0 | BC4: 1 | BD4: 0 | BE4: 0 | BF4: 137 | BG4: 0 | BH4: 0 | BI4: 0 | BJ4: 0 | BK4: 0 | BL4: 0 | BM4: 0 | BN4: 0 | BO4: 0 | BR4: 0 | BS4: 0 | BT4: 0 | BV4: 0 | BZ4: =SUM(T4:BY4) -> 473 | CA4: E-A | CB4: What is wrong with this? An interrupted occupation? | CC4: =SUM(BG4:BV4,AE4:AW4,AY4:BE4,T4:AC4)/BZ4 -> 0.27906977 | CD4: =BZ4-SUM(BF4,AX4,AW4,AD4,W4) -> 132 | CE4: =SUM(AX4:BV4) -> 303 | CF4: =SUM(BG4:BV4,AY4:BE4) -> 11 | CG4: =CF4/CE4 -> 0.03630363 | CH4: Memphis
A5: 10-P-4 | B5: Notgrass | C5: AR | D5: 3MS0015 | E5: Mississippi | F5: 986 | G5: 11N/09E/26 | H5: 3936400 | I5: 762620 | J5: 15 | L5: Large village site - no mounds | M5: Phillips | N5: 14724 | T5: 0 | U5: 0 | V5: 0 | W5: 0 | Y5: 0 | Z5: 0 | AA5: 0 | AC5: 0 | AD5: 14 | AE5: 7 | AF5: 0 | AG5: 2 | AH5: 0 | AJ5: 0 | AL5: 0 | AM5: 0 | AN5: 0 | AP5: 0 | AQ5: 0 | AR5: 0 | AS5: 0 | AT5: 0 | AV5: 0 | AW5: 0 | AX5: 2580 | AY5: 10 | AZ5: 6 | BA5: 2 | BB5: 0 | BC5: 3 | BD5: 2 | BE5: 0 | BF5: 552 | BG5: 4 | BH5: 0 | BI5: 3 | BJ5: 0 | BK5: 0 | BL5: 6 | BM5: 9 | BN5: 0 | BO5: 4 | BR5: 0 | BS5: 1 | BT5: 0 | BV5: 0 | BZ5: =SUM(T5:BY5) -> 3205 | CA5: B | CC5: =SUM(BG5:BV5,AE5:AW5,AY5:BE5,T5:AC5)/BZ5 -> 0.018408736 | CD5: =BZ5-SUM(BF5,AX5,AW5,AD5,W5) -> 59 | CE5: =SUM(AX5:BV5) -> 3182 | CF5: =SUM(BG5:BV5,AY5:BE5) -> 50 | CG5: =CF5/CE5 -> 0.015713388 | CH5: Memphis
A6: 10-Q-1 | B6: Upper Nodena | C6: AR | D6: 3MS0004 | E6: Mississippi | F6: 556 | G6: 11N/10E/1 | H6: 3943700 | I6: 773800 | J6: 15 | L6: Small mound, large village site and cemetery | M6: Phillips | N6: 14722 | O6: map | T6: 0 | U6: 0 | V6: 0 | W6: 0 | Y6: 0 | Z6: 0 | AA6: 0 | AC6: 0 | AD6: 8 | AE6: 0 | AF6: 0 | AG6: 0 | AH6: 0 | AJ6: 0 | AL6: 0 | AM6: 0 | AN6: 0 | AP6: 0 | AQ6: 0 | AR6: 0 | AS6: 0 | AT6: 0 | AV6: 0 | AW6: 1 | AX6: 1299 | AY6: 5 | AZ6: 3 | BA6: 3 | BB6: 1 | BC6: 0 | BD6: 0 | BE6: 0 | BF6: 1675 | BG6: 2 | BH6: 1 | BI6: 3 | BJ6: 0 | BK6: 0 | BL6: 25 | BM6: 0 | BN6: 0 | BO6: 4 | BR6: 0 | BS6: 0 | BT6: 0 | BV6: 0 | BZ6: =SUM(T6:BY6) -> 3030 | CA6: A | CC6: =SUM(BG6:BV6,AE6:AW6,AY6:BE6,T6:AC6)/BZ6 -> 0.015841584 | CD6: =BZ6-SUM(BF6,AX6,AW6,AD6,W6) -> 47 | CE6: =SUM(AX6:BV6) -> 3021 | CF6: =SUM(BG6:BV6,AY6:BE6) -> 47 | CG6: =CF6/CE6 -> 0.015557762 | CH6: Memphis
A7: 10-Q-3 | B7: Turnage | C7: AR | D7: 3MS0017 | E7: Mississippi | F7: 556 | G7: 11N/10E/13 | H7: 3940400 | I7: 773550 | J7: 15 | L7: Small mound and village site | M7: Phillips | N7: 14723 | O7: map | T7: 0 | U7: 0 | V7: 0 | W7: 26 | Y7: 12 | Z7: 45 | AA7: 1 | AC7: 0 | AD7: 45 | AE7: 56 | AF7: 5 | AG7: 46 | AH7: 0 | AJ7: 0 | AL7: 0 | AM7: 0 | AN7: 0 | AP7: 0 | AQ7: 0 | AR7: 0 | AS7: 0 | AT7: 0 | AV7: 0 | AW7: 0 | AX7: 58 | AY7: 0 | AZ7: 1 | BA7: 0 | BB7: 0 | BC7: 0 | BD7: 0 | BE7: 0 | BF7: 115 | BG7: 0 | BH7: 0 | BI7: 0 | BJ7: 0 | BK7: 0 | BL7: 1 | BM7: 0 | BN7: 0 | BO7: 0 | BR7: 0 | BS7: 0 | BT7: 0 | BV7: 0 | BZ7: =SUM(T7:BY7) -> 411 | CA7: E-A | CB7: What is wrong with this? An interrupted occupation? | CC7: =SUM(BG7:BV7,AE7:AW7,AY7:BE7,T7:AC7)/BZ7 -> 0.46958637 | CD7: =BZ7-SUM(BF7,AX7,AW7,AD7,W7) -> 167 | CE7: =SUM(AX7:BV7) -> 175 | CF7: =SUM(BG7:BV7,AY7:BE7) -> 2 | CG7: =CF7/CE7 -> 0.011428571 | CH7: Memphis
A8: 11-N-1 | B8: Parkin | C8: AR | D8: 3CS0029 | E8: Cross | F8: 472 | G8: 08N/05E/34 | H8: 3906400 | I8: 722250 | J8: 15 | T8: 0 | U8: 0 | V8: 0 | W8: 0 | Y8: 0 | Z8: 0 | AA8: 0 | AC8: 0 | AD8: 8 | AE8: 4 | AF8: 0 | AG8: 0 | AH8: 0 | AJ8: 0 | AL8: 0 | AM8: 0 | AN8: 0 | AP8: 0 | AQ8: 0 | AR8: 0 | AS8: 0 | AT8: 0 | AV8: 0 | AW8: 0 | AX8: 5468 | AY8: 865 | AZ8: 311 | BA8: 35 | BB8: 4 | BC8: 17 | BD8: 0 | BE8: 0 | BF8: 80 | BG8: 12 | BH8: 0 | BI8: 0 | BJ8: 0 | BK8: 0 | BL8: 53 | BM8: 0 | BN8: 0 | BO8: 6 | BR8: 0 | BS8: 0 | BT8: 0 | BV8: 0 | BZ8: =SUM(T8:BY8) -> 6863 | CA8: A | CC8: =SUM(BG8:BV8,AE8:AW8,AY8:BE8,T8:AC8)/BZ8 -> 0.1904415 | CD8: =BZ8-SUM(BF8,AX8,AW8,AD8,W8) -> 1307 | CE8: =SUM(AX8:BV8) -> 6851 | CF8: =SUM(BG8:BV8,AY8:BE8) -> 1303 | CG8: =CF8/CE8 -> 0.19019121 | CH8: St. Francis
A9: 11-N-10 | B9: Cross Country Club | C9: AR | D9: 3CS0068 | E9: Cross | F9: 405 | G9: 7N/04E/4 | H9: 3904500 | I9: 710900 | J9: 15 | L9: Small mound and village site | M9: Griffin, Phillips, Ford | N9: 14705 | T9: 0 | U9: 0 | V9: 0 | W9: 0 | Y9: 0 | Z9: 0 | AA9: 0 | AC9: 0 | AD9: 145 | AE9: 11 | AF9: 0 | AG9: 0 | AH9: 0 | AJ9: 0 | AL9: 0 | AM9: 0 | AN9: 0 | AP9: 0 | AQ9: 1 | AR9: 0 | AS9: 0 | AT9: 0 | AV9: 0 | AW9: 0 | AX9: 52 | AY9: 2 | AZ9: 0 | BA9: 0 | BB9: 0 | BC9: 0 | BD9: 0 | BE9: 0 | BF9: 0 | BG9: 0 | BH9: 0 | BI9: 0 | BJ9: 0 | BK9: 0 | BL9: 0 | BM9: 0 | BN9: 0 | BO9: 0 | BR9: 0 | BS9: 0 | BT9: 0 | BV9: 0 | BZ9: =SUM(T9:BY9) -> 211 | CA9: C | CC9: =SUM(BG9:BV9,AE9:AW9,AY9:BE9,T9:AC9)/BZ9 -> 0.066350711 | CD9: =BZ9-SUM(BF9,AX9,AW9,AD9,W9) -> 14 | CE9: =SUM(AX9:BV9) -> 54 | CF9: =SUM(BG9:BV9,AY9:BE9) -> 2 | CG9: =CF9/CE9 -> 0.037037037 | CH9: St. Francis
A10: 11-N-11 | B10: Delta | C10: AR | D10: 3CS0069 | E10: Cross | F10: 472 | G10: 08N/05E/17 | H10: 3910400 | I10: 719500 | J10: 15 | L10: Conical and rounded mounds | M10: Phillips, Ford | N10: 14710 | O10: map | T10: 0 | U10: 0 | V10: 0 | W10: 0 | Y10: 0 | Z10: 0 | AA10: 0 | AC10: 0 | AD10: 175 | AE10: 27 | AF10: 0 | AG10: 0 | AH10: 0 | AJ10: 0 | AL10: 0 | AM10: 0 | AN10: 0 | AP10: 0 | AQ10: 0 | AR10: 0 | AS10: 0 | AT10: 0 | AV10: 0 | AW10: 1 | AX10: 87 | AY10: 0 | AZ10: 1 | BA10: 0 | BB10: 0 | BC10: 0 | BD10: 0 | BE10: 0 | BF10: 0 | BG10: 0 | BH10: 0 | BI10: 0 | BJ10: 0 | BK10: 0 | BL10: 1 | BM10: 0 | BN10: 0 | BO10: 0 | BR10: 0 | BS10: 0 | BT10: 0 | BV10: 0 | BZ10: =SUM(T10:BY10) -> 292 | CA10: C | CC10: =SUM(BG10:BV10,AE10:AW10,AY10:BE10,T10:AC10)/BZ10 -> 0.10273973 | CD10: =BZ10-SUM(BF10,AX10,AW10,AD10,W10) -> 29 | CE10: =SUM(AX10:BV10) -> 89 | CF10: =SUM(BG10:BV10,AY10:BE10) -> 2 | CG10: =CF10/CE10 -> 0.02247191 | CH10: St. Francis
A11: 11-N-12 | B11: Turnbow | C11: AR | D11: 3CS0061 | E11: Cross | F11: 494 | G11: 09N/05E/2 | H11: 3924500 | I11: 724720 | J11: 15 | L11: Mound group, plaza arrangement | M11: Phillips, Ford | N11: 14710 | T11: 0 | U11: 0 | V11: 0 | W11: 0 | Y11: 0 | Z11: 0 | AA11: 0 | AC11: 0 | AD11: 1 | AE11: 0 | AF11: 0 | AG11: 0 | AH11: 0 | AJ11: 0 | AL11: 0 | AM11: 0 | AN11: 0 | AP11: 0 | AQ11: 0 | AR11: 0 | AS11: 0 | AT11: 0 | AV11: 1 | AW11: 0 | AX11: 2913 | AY11: 20 | AZ11: 87 | BA11: 1 | BB11: 0 | BC11: 7 | BD11: 0 | BE11: 0 | BF11: 10 | BG11: 0 | BH11: 0 | BI11: 0 | BJ11: 0 | BK11: 0 | BL11: 12 | BM11: 0 | BN11: 0 | BO11: 1 | BR11: 0 | BS11: 1 | BT11: 0 | BV11: 0 | BZ11: =SUM(T11:BY11) -> 3054 | CA11: B | CC11: =SUM(BG11:BV11,AE11:AW11,AY11:BE11,T11:AC11)/BZ11 -> 0.042567125 | CD11: =BZ11-SUM(BF11,AX11,AW11,AD11,W11) -> 130 | CE11: =SUM(AX11:BV11) -> 3052 | CF11: =SUM(BG11:BV11,AY11:BE11) -> 129 | CG11: =CF11/CE11 -> 0.042267366 | CH11: St. Francis
A12: 11-N-13 | B12: Williamson | C12: AR | D12: 3CS0026 | E12: Cross | F12: 472 | G12: 08N/05E/20 | H12: 3909500 | I12: 719950 | J12: 15 | L12: St. Francis type with mounds in plaza arrangement | M12: Phillips, Ford | N12: 14710 | O12: map | T12: 0 | U12: 0 | V12: 0 | W12: 0 | Y12: 0 | Z12: 0 | AA12: 0 | AC12: 0 | AD12: 6 | AE12: 0 | AF12: 0 | AG12: 0 | AH12: 0 | AJ12: 0 | AL12: 0 | AM12: 0 | AN12: 0 | AP12: 0 | AQ12: 0 | AR12: 0 | AS12: 0 | AT12: 0 | AV12: 0 | AW12: 0 | AX12: 4237 | AY12: 425 | AZ12: 212 | BA12: 0 | BB12: 1 | BC12: 17 | BD12: 0 | BE12: 0 | BF12: 12 | BG12: 2 | BH12: 0 | BI12: 0 | BJ12: 0 | BK12: 0 | BL12: 1 | BM12: 12 | BN12: 0 | BO12: 0 | BR12: 0 | BS12: 0 | BT12: 0 | BV12: 0 | BZ12: =SUM(T12:BY12) -> 4925 | CA12: B | CC12: =SUM(BG12:BV12,AE12:AW12,AY12:BE12,T12:AC12)/BZ12 -> 0.13604061 | CD12: =BZ12-SUM(BF12,AX12,AW12,AD12,W12) -> 670 | CE12: =SUM(AX12:BV12) -> 4919 | CF12: =SUM(BG12:BV12,AY12:BE12) -> 670 | CG12: =CF12/CE12 -> 0.13620655 | CH12: St. Francis
A13: 11-N-14 | B13: Twist Plantation No. 1 | C13: AR | D13: 3CS0070 | E13: Cross | F13: 494 | G13: 09N/05E/22 | H13: 3918950 | I13: 723125 | J13: 15 | L13: Small village site - no mounds | M13: Griffin, Phillips | N13: 14717 | T13: 0 | U13: 0 | V13: 0 | W13: 0 | Y13: 0 | Z13: 0 | AA13: 0 | AC13: 0 | AD13: 47 | AE13: 3 | AF13: 0 | AG13: 0 | AH13: 0 | AJ13: 0 | AL13: 0 | AM13: 0 | AN13: 0 | AP13: 0 | AQ13: 0 | AR13: 0 | AS13: 0 | AT13: 0 | AV13: 0 | AW13: 0 | AX13: 7 | AY13: 0 | AZ13: 0 | BA13: 0 | BB13: 0 | BC13: 0 | BD13: 0 | BE13: 0 | BF13: 0 | BG13: 0 | BH13: 0 | BI13: 0 | BJ13: 0 | BK13: 0 | BL13: 0 | BM13: 0 | BN13: 0 | BO13: 0 | BR13: 0 | BS13: 0 | BT13: 0 | BV13: 0 | BZ13: =SUM(T13:BY13) -> 57 | CA13: ?? | CC13: =SUM(BG13:BV13,AE13:AW13,AY13:BE13,T13:AC13)/BZ13 -> 0.052631579 | CD13: =BZ13-SUM(BF13,AX13,AW13,AD13,W13) -> 3 | CE13: =SUM(AX13:BV13) -> 7 | CF13: =SUM(BG13:BV13,AY13:BE13) -> 0 | CG13: =CF13/CE13 -> 0 | CH13: St. Francis
A14: 11-N-15 | B14: Fortune | C14: AR | D14: 3CS0071 | E14: Cross | F14: 494 | G14: 09N/05E/10 | H14: 3921670 | I14: 722850 | J14: 15 | L14: Elevated village site of St. Francis type | M14: Griffin, Phillips | N14: 14717 | O14: map | T14: 0 | U14: 0 | V14: 0 | W14: 0 | Y14: 0 | Z14: 0 | AA14: 0 | AC14: 0 | AD14: 0 | AE14: 0 | AF14: 0 | AG14: 0 | AH14: 0 | AJ14: 0 | AL14: 0 | AM14: 0 | AN14: 0 | AP14: 0 | AQ14: 0 | AR14: 0 | AS14: 0 | AT14: 0 | AV14: 0 | AW14: 0 | AX14: 485 | AY14: 143 | AZ14: 53 | BA14: 0 | BB14: 0 | BC14: 0 | BD14: 0 | BE14: 0 | BF14: 0 | BG14: 0 | BH14: 0 | BI14: 0 | BJ14: 0 | BK14: 1 | BL14: 3 | BM14: 0 | BN14: 0 | BO14: 0 | BR14: 0 | BS14: 0 | BT14: 0 | BV14: 0 | BZ14: =SUM(T14:BY14) -> 685 | CA14: A | CC14: =SUM(BG14:BV14,AE14:AW14,AY14:BE14,T14:AC14)/BZ14 -> 0.2919708 | CD14: =BZ14-SUM(BF14,AX14,AW14,AD14,W14) -> 200 | CE14: =SUM(AX14:BV14) -> 685 | CF14: =SUM(BG14:BV14,AY14:BE14) -> 200 | CG14: =CF14/CE14 -> 0.2919708 | CH14: St. Francis
A15: 11-N-16 | B15: Twist No. 2 | C15: AR | D15: 3CS0072 | E15: Cross | F15: 494 | G15: 09N/05E/14 | H15: 3920400 | I15: 724150 | J15: 15 | L15: Large group of mounds scattered over considerable area | M15: Griffin, Phillips | N15: 14717 | O15: map | T15: 0 | U15: 0 | V15: 0 | W15: 0 | Y15: 0 | Z15: 0 | AA15: 0 | AC15: 0 | AD15: 0 | AE15: 0 | AF15: 0 | AG15: 0 | AH15: 0 | AJ15: 0 | AL15: 0 | AM15: 0 | AN15: 0 | AP15: 0 | AQ15: 0 | AR15: 0 | AS15: 0 | AT15: 0 | AV15: 0 | AW15: 0 | AX15: 102 | AY15: 0 | AZ15: 0 | BA15: 0 | BB15: 0 | BC15: 0 | BD15: 0 | BE15: 0 | BF15: 1 | BG15: 0 | BH15: 0 | BI15: 0 | BJ15: 0 | BK15: 0 | BL15: 0 | BM15: 0 | BN15: 0 | BO15: 0 | BR15: 0 | BS15: 0 | BT15: 0 | BV15: 0 | BZ15: =SUM(T15:BY15) -> 103 | CA15: B | CC15: =SUM(BG15:BV15,AE15:AW15,AY15:BE15,T15:AC15)/BZ15 -> 0 | CD15: =BZ15-SUM(BF15,AX15,AW15,AD15,W15) -> 0 | CE15: =SUM(AX15:BV15) -> 103 | CF15: =SUM(BG15:BV15,AY15:BE15) -> 0 | CG15: =CF15/CE15 -> 0 | CH15: St. Francis
A16: 11-N-2 | B16: Rogers | C16: AR | D16: 3CS0062 | E16: Cross | F16: 472 | G16: 08N/05E/26 | H16: 3907350 | I16: 724440 | J16: 15 | L16: Five small conical mounds | M16: Griffin, Phillips, Ford | N16: 14699 | T16: 0 | U16: 0 | V16: 0 | W16: 0 | Y16: 0 | Z16: 0 | AA16: 0 | AC16: 0 | AD16: 470 | AE16: 120 | AF16: 0 | AG16: 0 | AH16: 0 | AJ16: 0 | AL16: 0 | AM16: 0 | AN16: 0 | AP16: 0 | AQ16: 1 | AR16: 0 | AS16: 0 | AT16: 0 | AV16: 0 | AW16: 1 | AX16: 33 | AY16: 2 | AZ16: 0 | BA16: 0 | BB16: 0 | BC16: 0 | BD16: 0 | BE16: 0 | BF16: 0 | BG16: 0 | BH16: 0 | BI16: 0 | BJ16: 0 | BK16: 0 | BL16: 0 | BM16: 0 | BN16: 0 | BO16: 0 | BR16: 0 | BS16: 0 | BT16: 0 | BV16: 0 | BZ16: =SUM(T16:BY16) -> 627 | CA16: D | CC16: =SUM(BG16:BV16,AE16:AW16,AY16:BE16,T16:AC16)/BZ16 -> 0.19776715 | CD16: =BZ16-SUM(BF16,AX16,AW16,AD16,W16) -> 123 | CE16: =SUM(AX16:BV16) -> 35 | CF16: =SUM(BG16:BV16,AY16:BE16) -> 2 | CG16: =CF16/CE16 -> 0.057142857 | CH16: St. Francis
A17: 11-N-3 | B17: Roberts | C17: AR | D17: 3CS0063 | E17: Cross | F17: 472 | G17: 08/05E/26 | H17: 3908400 | I17: 725230 | J17: 15 | L17: Four low rounded mounds | M17: Phillips, Griffin, Ford | N17: 14699 | O17: map | T17: 0 | U17: 0 | V17: 0 | W17: 0 | Y17: 0 | Z17: 0 | AA17: 0 | AC17: 0 | AD17: 725 | AE17: 204 | AF17: 0 | AG17: 0 | AH17: 0 | AJ17: 0 | AL17: 0 | AM17: 0 | AN17: 0 | AP17: 0 | AQ17: 1 | AR17: 0 | AS17: 0 | AT17: 0 | AV17: 0 | AW17: 3 | AX17: 50 | AY17: 3 | AZ17: 1 | BA17: 0 | BB17: 0 | BC17: 0 | BD17: 0 | BE17: 0 | BF17: 0 | BG17: 0 | BH17: 0 | BI17: 0 | BJ17: 0 | BK17: 0 | BL17: 0 | BM17: 0 | BN17: 0 | BO17: 0 | BR17: 0 | BS17: 0 | BT17: 0 | BV17: 0 | BZ17: =SUM(T17:BY17) -> 987 | CA17: D | CC17: =SUM(BG17:BV17,AE17:AW17,AY17:BE17,T17:AC17)/BZ17 -> 0.2147923 | CD17: =BZ17-SUM(BF17,AX17,AW17,AD17,W17) -> 209 | CE17: =SUM(AX17:BV17) -> 54 | CF17: =SUM(BG17:BV17,AY17:BE17) -> 4 | CG17: =CF17/CE17 -> 0.074074074 | CH17: St. Francis
A18: 11-N-4 | B18: Neeley's Ferry | C18: AR | D18: 3CS0024 | E18: Cross | F18: 472 | G18: 08N/05E/34 | H18: 3913500 | I18: 723480 | J18: 15 | L18: Large mounds and village site | M18: Ford, Griffin | N18: 14700 | O18: map | T18: 0 | U18: 0 | V18: 0 | W18: 0 | Y18: 0 | Z18: 0 | AA18: 0 | AC18: 0 | AD18: 6 | AE18: 6 | AF18: 0 | AG18: 0 | AH18: 0 | AJ18: 0 | AL18: 0 | AM18: 0 | AN18: 0 | AP18: 0 | AQ18: 0 | AR18: 0 | AS18: 0 | AT18: 0 | AV18: 0 | AW18: 0 | AX18: 5992 | AY18: 760 | AZ18: 466 | BA18: 9 | BB18: 0 | BC18: 5 | BD18: 4 | BE18: 3 | BF18: 2 | BG18: 4 | BH18: 0 | BI18: 0 | BJ18: 0 | BK18: 0 | BL18: 14 | BM18: 0 | BN18: 0 | BO18: 4 | BR18: 0 | BS18: 0 | BT18: 0 | BV18: 0 | BZ18: =SUM(T18:BY18) -> 7275 | CA18: A | CC18: =SUM(BG18:BV18,AE18:AW18,AY18:BE18,T18:AC18)/BZ18 -> 0.17525773 | CD18: =BZ18-SUM(BF18,AX18,AW18,AD18,W18) -> 1275 | CE18: =SUM(AX18:BV18) -> 7263 | CF18: =SUM(BG18:BV18,AY18:BE18) -> 1269 | CG18: =CF18/CE18 -> 0.17472119 | CH18: St. Francis
A19: 11-N-5 | B19: White Place | C19: AR | D19: 3CS0064 | E19: Cross | F19: 472 | G19: 08N/05E/34 | H19: 3913410 | I19: 722900 | J19: 15 | L19: Small conical mound | M19: Griffin, Ford | N19: 14700 | O19: map | T19: 0 | U19: 0 | V19: 0 | W19: 0 | Y19: 0 | Z19: 0 | AA19: 0 | AC19: 0 | AD19: 29 | AE19: 3 | AF19: 0 | AG19: 0 | AH19: 0 | AJ19: 0 | AL19: 0 | AM19: 0 | AN19: 0 | AP19: 0 | AQ19: 0 | AR19: 0 | AS19: 0 | AT19: 0 | AV19: 0 | AW19: 0 | AX19: 6 | AY19: 0 | AZ19: 0 | BA19: 0 | BB19: 0 | BC19: 0 | BD19: 0 | BE19: 0 | BF19: 0 | BG19: 0 | BH19: 0 | BI19: 0 | BJ19: 0 | BK19: 0 | BL19: 0 | BM19: 0 | BN19: 0 | BO19: 0 | BR19: 0 | BS19: 0 | BT19: 0 | BV19: 0 | BZ19: =SUM(T19:BY19) -> 38 | CA19: ?? | CC19: =SUM(BG19:BV19,AE19:AW19,AY19:BE19,T19:AC19)/BZ19 -> 0.078947368 | CD19: =BZ19-SUM(BF19,AX19,AW19,AD19,W19) -> 3 | CE19: =SUM(AX19:BV19) -> 6 | CF19: =SUM(BG19:BV19,AY19:BE19) -> 0 | CG19: =CF19/CE19 -> 0 | CH19: St. Francis
A20: 11-N-6 | B20: Block Mounds | C20: AR | D20: 3CS0065 | E20: Cross | F20: 472 | G20: 08N/05E/19 | H20: 3906950 | I20: 720220 | J20: 15 | L20: Mound group in plaza arrangement | M20: Phillips, Griffin, Ford | N20: 14702 | O20: map | T20: 0 | U20: 0 | V20: 0 | W20: 0 | Y20: 0 | Z20: 0 | AA20: 0 | AC20: 0 | AD20: 53 | AE20: 4 | AF20: 0 | AG20: 0 | AH20: 0 | AJ20: 0 | AL20: 0 | AM20: 0 | AN20: 0 | AP20: 0 | AQ20: 0 | AR20: 0 | AS20: 0 | AT20: 0 | AV20: 0 | AW20: 1 | AX20: 134 | AY20: 0 | AZ20: 0 | BA20: 0 | BB20: 0 | BC20: 0 | BD20: 0 | BE20: 0 | BF20: 1 | BG20: 0 | BH20: 0 | BI20: 0 | BJ20: 0 | BK20: 0 | BL20: 0 | BM20: 0 | BN20: 0 | BO20: 0 | BR20: 0 | BS20: 0 | BT20: 0 | BV20: 0 | BZ20: =SUM(T20:BY20) -> 193 | CA20: C | CC20: =SUM(BG20:BV20,AE20:AW20,AY20:BE20,T20:AC20)/BZ20 -> 0.025906736 | CD20: =BZ20-SUM(BF20,AX20,AW20,AD20,W20) -> 4 | CE20: =SUM(AX20:BV20) -> 135 | CF20: =SUM(BG20:BV20,AY20:BE20) -> 0 | CG20: =CF20/CE20 -> 0 | CH20: St. Francis
A21: 11-N-7 | B21: Harold | C21: AR | D21: 3CS0066 | E21: Cross | F21: 472 | G21: 08N/05E/32 | H21: =LOOKUP(A21,'[1]AMASDA DATA'!B13:B189,'[1]AMASDA DATA'!H13:H189) -> 3925160 | I21: =LOOKUP(A21,'[1]AMASDA DATA'!B13:B189,'[1]AMASDA DATA'!I13:I189) -> 690340 | J21: 15 | L21: Small village site | M21: Griffin, Phillips, Ford | N21: 14702 | T21: 0 | U21: 0 | V21: 0 | W21: 0 | Y21: 0 | Z21: 0 | AA21: 0 | AC21: 0 | AD21: 35 | AE21: 10 | AF21: 0 | AG21: 0 | AH21: 0 | AJ21: 0 | AL21: 0 | AM21: 0 | AN21: 0 | AP21: 0 | AQ21: 0 | AR21: 0 | AS21: 0 | AT21: 0 | AV21: 0 | AW21: 0 | AX21: 35 | AY21: 0 | AZ21: 0 | BA21: 0 | BB21: 0 | BC21: 0 | BD21: 0 | BE21: 0 | BF21: 0 | BG21: 0 | BH21: 0 | BI21: 0 | BJ21: 0 | BK21: 0 | BL21: 0 | BM21: 0 | BN21: 0 | BO21: 0 | BR21: 0 | BS21: 0 | BT21: 0 | BV21: 0 | BZ21: =SUM(T21:BY21) -> 80 | CA21: ?? | CC21: =SUM(BG21:BV21,AE21:AW21,AY21:BE21,T21:AC21)/BZ21 -> 0.125 | CD21: =BZ21-SUM(BF21,AX21,AW21,AD21,W21) -> 10 | CE21: =SUM(AX21:BV21) -> 35 | CF21: =SUM(BG21:BV21,AY21:BE21) -> 0 | CG21: =CF21/CE21 -> 0 | CH21: St. Francis
A22: 11-N-8 | B22: Williams | C22: AR | D22: 3CS0067 | E22: Cross | F22: 472 | G22: 08N/05E/17 | H22: 3911040 | I22: 719500 | J22: 15 | L22: Mound group and village site | M22: Ford, Griffin, Phillips | N22: 14702 | O22: map | T22: 0 | U22: 0 | V22: 0 | W22: 0 | Y22: 0 | Z22: 0 | AA22: 0 | AC22: 0 | AD22: 107 | AE22: 18 | AF22: 0 | AG22: 0 | AH22: 0 | AJ22: 0 | AL22: 0 | AM22: 0 | AN22: 0 | AP22: 0 | AQ22: 0 | AR22: 0 | AS22: 0 | AT22: 0 | AV22: 0 | AW22: 0 | AX22: 53 | AY22: 1 | AZ22: 0 | BA22: 0 | BB22: 0 | BC22: 0 | BD22: 0 | BE22: 0 | BF22: 0 | BG22: 0 | BH22: 0 | BI22: 0 | BJ22: 0 | BK22: 0 | BL22: 0 | BM22: 0 | BN22: 0 | BO22: 0 | BR22: 0 | BS22: 0 | BT22: 0 | BV22: 0 | BZ22: =SUM(T22:BY22) -> 179 | CA22: C | CC22: =SUM(BG22:BV22,AE22:AW22,AY22:BE22,T22:AC22)/BZ22 -> 0.10614525 | CD22: =BZ22-SUM(BF22,AX22,AW22,AD22,W22) -> 19 | CE22: =SUM(AX22:BV22) -> 54 | CF22: =SUM(BG22:BV22,AY22:BE22) -> 1 | CG22: =CF22/CE22 -> 0.018518519 | CH22: St. Francis
A23: 11-N-9 | B23: Vernon Paul | C23: AR | D23: 3CS0025 | E23: Cross | F23: 472 | G23: 08N/05E/11 | H23: 3913000 | I23: 725000 | J23: 15 | L23: Large town site of St. Francis type | M23: Griffin, Phillips, Ford | N23: 14702 | T23: 0 | U23: 0 | V23: 0 | W23: 0 | Y23: 0 | Z23: 0 | AA23: 0 | AC23: 0 | AD23: 0 | AE23: 0 | AF23: 0 | AG23: 0 | AH23: 0 | AJ23: 0 | AL23: 0 | AM23: 0 | AN23: 0 | AP23: 0 | AQ23: 0 | AR23: 0 | AS23: 0 | AT23: 0 | AV23: 0 | AW23: 0 | AX23: 1807 | AY23: 528 | AZ23: 191 | BA23: 19 | BB23: 0 | BC23: 0 | BD23: 0 | BE23: 0 | BF23: 2 | BG23: 7 | BH23: 0 | BI23: 0 | BJ23: 0 | BK23: 0 | BL23: 13 | BM23: 0 | BN23: 0 | BO23: 0 | BR23: 0 | BS23: 0 | BT23: 0 | BV23: 0 | BZ23: =SUM(T23:BY23) -> 2567 | CA23: A | CC23: =SUM(BG23:BV23,AE23:AW23,AY23:BE23,T23:AC23)/BZ23 -> 0.29528633 | CD23: =BZ23-SUM(BF23,AX23,AW23,AD23,W23) -> 758 | CE23: =SUM(AX23:BV23) -> 2567 | CF23: =SUM(BG23:BV23,AY23:BE23) -> 758 | CG23: =CF23/CE23 -> 0.29528633 | CH23: St. Francis
A24: 11-O-1 | B24: Pittman | C24: AR | D24: 3PO0033 | E24: Poinsett | F24: 410 | G24: 10N/06E/21 | H24: 3928100 | I24: 730000 | J24: 15 | L24: Small conical mounds. No associated village site. | M24: Phillips, Ford | N24: 14711 | O24: map | T24: 0 | U24: 0 | V24: 0 | W24: 0 | Y24: 0 | Z24: 0 | AA24: 0 | AC24: 0 | AD24: 1 | AE24: 2 | AF24: 0 | AG24: 0 | AH24: 0 | AJ24: 0 | AL24: 0 | AM24: 0 | AN24: 0 | AP24: 0 | AQ24: 0 | AR24: 0 | AS24: 0 | AT24: 0 | AV24: 0 | AW24: 0 | AX24: 25 | AY24: 0 | AZ24: 1 | BA24: 0 | BB24: 0 | BC24: 0 | BD24: 0 | BE24: 0 | BF24: 3 | BG24: 0 | BH24: 0 | BI24: 0 | BJ24: 0 | BK24: 0 | BL24: 0 | BM24: 1 | BN24: 0 | BO24: 0 | BR24: 0 | BS24: 0 | BT24: 0 | BV24: 0 | BZ24: =SUM(T24:BY24) -> 33 | CA24: ?? | CC24: =SUM(BG24:BV24,AE24:AW24,AY24:BE24,T24:AC24)/BZ24 -> 0.12121212 | CD24: =BZ24-SUM(BF24,AX24,AW24,AD24,W24) -> 4 | CE24: =SUM(AX24:BV24) -> 30 | CF24: =SUM(BG24:BV24,AY24:BE24) -> 2 | CG24: =CF24/CE24 -> 0.066666667 | CH24: St. Francis
A25: 11-O-10 | B25: Barton Ranch | C25: AR | D25: 3CT0018 | E25: Crittenden | F25: 410 | G25: 09N/07E/30 | H25: 3918000 | I25: 737150 | J25: 15 | L25: Rectangular town site of St. Francis type, no mounds | M25: Griffin, Phillips | N25: 14717 | O25: Plane Table Map | T25: 0 | U25: 0 | V25: 0 | W25: 0 | Y25: 0 | Z25: 0 | AA25: 0 | AC25: 0 | AD25: 11 | AE25: 0 | AF25: 0 | AG25: 0 | AH25: 0 | AJ25: 0 | AL25: 0 | AM25: 0 | AN25: 0 | AP25: 0 | AQ25: 0 | AR25: 0 | AS25: 0 | AT25: 0 | AV25: 0 | AW25: 0 | AX25: 4056 | AY25: 395 | AZ25: 207 | BA25: 4 | BB25: 0 | BC25: 16 | BD25: 9 | BE25: 0 | BF25: 8 | BG25: 0 | BH25: 0 | BI25: 0 | BJ25: 0 | BK25: 1 | BL25: 6 | BM25: 0 | BN25: 0 | BO25: 0 | BR25: 0 | BS25: 0 | BT25: 0 | BV25: 0 | BZ25: =SUM(T25:BY25) -> 4713 | CA25: B | CC25: =SUM(BG25:BV25,AE25:AW25,AY25:BE25,T25:AC25)/BZ25 -> 0.13537025 | CD25: =BZ25-SUM(BF25,AX25,AW25,AD25,W25) -> 638 | CE25: =SUM(AX25:BV25) -> 4702 | CF25: =SUM(BG25:BV25,AY25:BE25) -> 638 | CG25: =CF25/CE25 -> 0.13568694 | CH25: St. Francis
A26: 11-O-11 | B26: Prosperity | C26: AR | D26: 3CT0024 | E26: Crittenden | F26: 223 | G26: 08N/07E/6 | H26: 3914900 | I26: 736700 | J26: 15 | L26: Small mound and village site, very little material | M26: Griffin, Phillips | N26: 14717 | O26: Map | T26: 0 | U26: 0 | V26: 0 | W26: 0 | Y26: 0 | Z26: 0 | AA26: 0 | AC26: 0 | AD26: 98 | AE26: 0 | AF26: 0 | AG26: 0 | AH26: 0 | AJ26: 0 | AL26: 0 | AM26: 0 | AN26: 0 | AP26: 0 | AQ26: 0 | AR26: 0 | AS26: 0 | AT26: 0 | AV26: 0 | AW26: 0 | AX26: 6 | AY26: 2 | AZ26: 0 | BA26: 0 | BB26: 0 | BC26: 0 | BD26: 0 | BE26: 0 | BF26: 0 | BG26: 0 | BH26: 0 | BI26: 0 | BJ26: 0 | BK26: 0 | BL26: 0 | BM26: 0 | BN26: 0 | BO26: 0 | BR26: 0 | BS26: 0 | BT26: 0 | BV26: 0 | BZ26: =SUM(T26:BY26) -> 106 | CA26: C | CC26: =SUM(BG26:BV26,AE26:AW26,AY26:BE26,T26:AC26)/BZ26 -> 0.018867925 | CD26: =BZ26-SUM(BF26,AX26,AW26,AD26,W26) -> 2 | CE26: =SUM(AX26:BV26) -> 8 | CF26: =SUM(BG26:BV26,AY26:BE26) -> 2 | CG26: =CF26/CE26 -> 0.25 | CH26: St. Francis
A27: 11-O-2 | B27: Webster Cemetery | C27: AR | D27: 3PO0034 | E27: Poinsett | F27: 410 | G27: 10N/07E/18 | H27: 3929800 | I27: 737670 | J27: 15 | L27: Small conical mound | M27: Ford, Phillips | N27: 14711 | T27: 0 | U27: 0 | V27: 0 | W27: 0 | Y27: 0 | Z27: 0 | AA27: 0 | AC27: 0 | AD27: 4 | AE27: 0 | AF27: 0 | AG27: 0 | AH27: 0 | AJ27: 0 | AL27: 0 | AM27: 0 | AN27: 0 | AP27: 0 | AQ27: 0 | AR27: 0 | AS27: 0 | AT27: 0 | AV27: 0 | AW27: 0 | AX27: 15 | AY27: 0 | AZ27: 0 | BA27: 0 | BB27: 0 | BC27: 0 | BD27: 0 | BE27: 0 | BF27: 0 | BG27: 0 | BH27: 0 | BI27: 0 | BJ27: 0 | BK27: 0 | BL27: 0 | BM27: 0 | BN27: 0 | BO27: 0 | BR27: 0 | BS27: 0 | BT27: 0 | BV27: 0 | BZ27: =SUM(T27:BY27) -> 19 | CA27: ?? | CC27: =SUM(BG27:BV27,AE27:AW27,AY27:BE27,T27:AC27)/BZ27 -> 0 | CD27: =BZ27-SUM(BF27,AX27,AW27,AD27,W27) -> 0 | CE27: =SUM(AX27:BV27) -> 15 | CF27: =SUM(BG27:BV27,AY27:BE27) -> 0 | CG27: =CF27/CE27 -> 0 | CH27: St. Francis
A28: 11-O-4 | B28: Cummins | C28: AR | D28: 3PO243 | E28: Poinsett | F28: 28 | G28: 11N/04E/2 | H28: 3944100 | I28: 714360 | J28: 15 | L28: Group of mounds | M28: Phillips, Ford | N28: 14711 | O28: map | T28: 0 | U28: 0 | V28: 0 | W28: 0 | Y28: 0 | Z28: 0 | AA28: 0 | AC28: 0 | AD28: 6 | AE28: 0 | AF28: 0 | AG28: 0 | AH28: 0 | AJ28: 0 | AL28: 0 | AM28: 0 | AN28: 0 | AP28: 0 | AQ28: 0 | AR28: 0 | AS28: 0 | AT28: 0 | AV28: 0 | AW28: 0 | AX28: 443 | AY28: 206 | AZ28: 45 | BA28: 3 | BB28: 2 | BC28: 0 | BD28: 0 | BE28: 0 | BF28: 9 | BG28: 3 | BH28: 0 | BI28: 0 | BJ28: 0 | BK28: 0 | BL28: 2 | BM28: 0 | BN28: 0 | BO28: 0 | BR28: 0 | BS28: 0 | BT28: 0 | BV28: 0 | BZ28: =SUM(T28:BY28) -> 719 | CA28: A | CC28: =SUM(BG28:BV28,AE28:AW28,AY28:BE28,T28:AC28)/BZ28 -> 0.36300417 | CD28: =BZ28-SUM(BF28,AX28,AW28,AD28,W28) -> 261 | CE28: =SUM(AX28:BV28) -> 713 | CF28: =SUM(BG28:BV28,AY28:BE28) -> 261 | CG28: =CF28/CE28 -> 0.36605891 | CH28: St. Francis
A29: 11-O-5 | B29: Emory | C29: AR | D29: 3CT0020 | E29: Crittenden | F29: 410 | G29: 09N/06E/2 | H29: 3924190 | I29: 734640 | J29: 15 | L29: Small conical mound | M29: Phillips, Ford | N29: 14711 | T29: 0 | U29: 0 | V29: 0 | W29: 0 | Y29: 0 | Z29: 0 | AA29: 0 | AC29: 0 | AD29: 79 | AE29: 13 | AF29: 0 | AG29: 2 | AH29: 0 | AJ29: 0 | AL29: 0 | AM29: 0 | AN29: 0 | AP29: 1 | AQ29: 0 | AR29: 0 | AS29: 0 | AT29: 0 | AV29: 0 | AW29: 0 | AX29: 17 | AY29: 1 | AZ29: 0 | BA29: 0 | BB29: 0 | BC29: 0 | BD29: 0 | BE29: 0 | BF29: 4 | BG29: 0 | BH29: 0 | BI29: 0 | BJ29: 0 | BK29: 0 | BL29: 0 | BM29: 0 | BN29: 0 | BO29: 0 | BR29: 0 | BS29: 0 | BT29: 0 | BV29: 0 | BZ29: =SUM(T29:BY29) -> 117 | CA29: C | CC29: =SUM(BG29:BV29,AE29:AW29,AY29:BE29,T29:AC29)/BZ29 -> 0.14529915 | CD29: =BZ29-SUM(BF29,AX29,AW29,AD29,W29) -> 17 | CE29: =SUM(AX29:BV29) -> 22 | CF29: =SUM(BG29:BV29,AY29:BE29) -> 1 | CG29: =CF29/CE29 -> 0.045454545 | CH29: St. Francis
A30: 11-O-6 | B30: Pinkston | C30: AR | D30: 3PO0036 | E30: Poinsett | F30: 410 | G30: 10N/06E/35 | H30: 3924830 | I30: 734650 | J30: 15 | L30: Small conical mound and village site | M30: Ford, Phillips | N30: 14711 | T30: 0 | U30: 0 | V30: 0 | W30: 0 | Y30: 0 | Z30: 0 | AA30: 0 | AC30: 0 | AD30: 121 | AE30: 15 | AF30: 0 | AG30: 0 | AH30: 0 | AJ30: 0 | AL30: 0 | AM30: 0 | AN30: 0 | AP30: 0 | AQ30: 0 | AR30: 0 | AS30: 0 | AT30: 0 | AV30: 0 | AW30: 0 | AX30: 22 | AY30: 0 | AZ30: 0 | BA30: 0 | BB30: 0 | BC30: 0 | BD30: 0 | BE30: 0 | BF30: 0 | BG30: 0 | BH30: 0 | BI30: 0 | BJ30: 0 | BK30: 0 | BL30: 0 | BM30: 0 | BN30: 0 | BO30: 0 | BR30: 0 | BS30: 0 | BT30: 0 | BV30: 0 | BZ30: =SUM(T30:BY30) -> 158 | CA30: D | CC30: =SUM(BG30:BV30,AE30:AW30,AY30:BE30,T30:AC30)/BZ30 -> 0.094936709 | CD30: =BZ30-SUM(BF30,AX30,AW30,AD30,W30) -> 15 | CE30: =SUM(AX30:BV30) -> 22 | CF30: =SUM(BG30:BV30,AY30:BE30) -> 0 | CG30: =CF30/CE30 -> 0 | CH30: St. Francis
A31: 11-O-7 | B31: Lewis | C31: AR | D31: 3CT0021 | E31: Crittenden | F31: 223 | G31: 08N/06E/16 | H31: 3911480 | I31: 730800 | J31: 15 | L31: One rectangular and several conical mounds and village site | M31: Phillips | N31: 14716 | O31: map | T31: 0 | U31: 0 | V31: 0 | W31: 0 | Y31: 0 | Z31: 0 | AA31: 0 | AC31: 0 | AD31: 1140 | AE31: 126 | AF31: 0 | AG31: 0 | AH31: 0 | AJ31: 0 | AL31: 0 | AM31: 0 | AN31: 0 | AP31: 0 | AQ31: 0 | AR31: 2 | AS31: 0 | AT31: 0 | AV31: 0 | AW31: 0 | AX31: 204 | AY31: 0 | AZ31: 1 | BA31: 0 | BB31: 0 | BC31: 0 | BD31: 0 | BE31: 0 | BF31: 0 | BG31: 0 | BH31: 0 | BI31: 0 | BJ31: 0 | BK31: 0 | BL31: 1 | BM31: 0 | BN31: 0 | BO31: 0 | BR31: 0 | BS31: 0 | BT31: 0 | BV31: 0 | BZ31: =SUM(T31:BY31) -> 1474 | CA31: C | CC31: =SUM(BG31:BV31,AE31:AW31,AY31:BE31,T31:AC31)/BZ31 -> 0.088195387 | CD31: =BZ31-SUM(BF31,AX31,AW31,AD31,W31) -> 130 | CE31: =SUM(AX31:BV31) -> 206 | CF31: =SUM(BG31:BV31,AY31:BE31) -> 2 | CG31: =CF31/CE31 -> 0.0097087379 | CH31: St. Francis
A32: 11-O-8 | B32: Richard's Place Bridge | C32: AR | D32: 3CT022 | E32: Crittenden | F32: 223 | G32: 08N/06E/10 | H32: 3913360 | I32: 732350 | J32: 15 | L32: Small M. Mississippian site with remnant of a mound | M32: Phillips | N32: 14716 | O32: Map | T32: 0 | U32: 0 | V32: 0 | W32: 0 | Y32: 0 | Z32: 0 | AA32: 0 | AC32: 0 | AD32: 5 | AE32: 1 | AF32: 0 | AG32: 0 | AH32: 0 | AJ32: 0 | AL32: 0 | AM32: 0 | AN32: 0 | AP32: 0 | AQ32: 0 | AR32: 0 | AS32: 0 | AT32: 0 | AV32: 0 | AW32: 0 | AX32: 115 | AY32: 14 | AZ32: 10 | BA32: 2 | BB32: 0 | BC32: 0 | BD32: 0 | BE32: 0 | BF32: 1 | BG32: 0 | BH32: 0 | BI32: 0 | BJ32: 0 | BK32: 0 | BL32: 2 | BM32: 0 | BN32: 0 | BO32: 0 | BR32: 0 | BS32: 0 | BT32: 0 | BV32: 0 | BZ32: =SUM(T32:BY32) -> 150 | CA32: B | CC32: =SUM(BG32:BV32,AE32:AW32,AY32:BE32,T32:AC32)/BZ32 -> 0.19333333 | CD32: =BZ32-SUM(BF32,AX32,AW32,AD32,W32) -> 29 | CE32: =SUM(AX32:BV32) -> 144 | CF32: =SUM(BG32:BV32,AY32:BE32) -> 28 | CG32: =CF32/CE32 -> 0.19444444 | CH32: St. Francis
A33: 11-O-9 | B33: Gilliland | C33: AR | D33: 3CT0023 | E33: Crittenden | F33: 223 | G33: 09N/07E/31 | H33: 3916540 | I33: 736740 | J33: 15 | L33: Small mound and village site | M33: Phillips | N33: 14716 | O33: Map | T33: 0 | U33: 0 | V33: 0 | W33: 0 | Y33: 0 | Z33: 0 | AA33: 0 | AC33: 0 | AD33: 55 | AE33: 6 | AF33: 0 | AG33: 0 | AH33: 0 | AJ33: 0 | AL33: 0 | AM33: 0 | AN33: 0 | AP33: 0 | AQ33: 0 | AR33: 0 | AS33: 0 | AT33: 0 | AV33: 0 | AW33: 0 | AX33: 2 | AY33: 8 | AZ33: 0 | BA33: 0 | BB33: 0 | BC33: 0 | BD33: 0 | BE33: 0 | BF33: 0 | BG33: 0 | BH33: 0 | BI33: 0 | BJ33: 0 | BK33: 0 | BL33: 0 | BM33: 0 | BN33: 0 | BO33: 0 | BR33: 0 | BS33: 0 | BT33: 0 | BV33: 0 | BZ33: =SUM(T33:BY33) -> 71 | CA33: C | CC33: =SUM(BG33:BV33,AE33:AW33,AY33:BE33,T33:AC33)/BZ33 -> 0.1971831 | CD33: =BZ33-SUM(BF33,AX33,AW33,AD33,W33) -> 14 | CE33: =SUM(AX33:BV33) -> 10 | CF33: =SUM(BG33:BV33,AY33:BE33) -> 8 | CG33: =CF33/CE33 -> 0.8 | CH33: St. Francis
A34: 11-P-1 | B34: Shawnee Village | C34: AR | D34: 3MS0007 | E34: Mississippi | F34: 603 | G34: 10N/09E/10 | H34: 3931860 | I34: 761300 | J34: 15 | L34: Mounds and village site | M34: Phillips | N34: 14723 | O34: map | T34: 0 | U34: 0 | V34: 0 | W34: 0 | Y34: 0 | Z34: 0 | AA34: 0 | AC34: 0 | AD34: 3 | AE34: 6 | AF34: 0 | AG34: 0 | AH34: 0 | AJ34: 0 | AL34: 0 | AM34: 0 | AN34: 0 | AP34: 0 | AQ34: 0 | AR34: 0 | AS34: 0 | AT34: 0 | AV34: 0 | AW34: 1 | AX34: 47 | AY34: 0 | AZ34: 1 | BA34: 0 | BB34: 0 | BC34: 0 | BD34: 0 | BE34: 0 | BF34: 43 | BG34: 0 | BH34: 0 | BI34: 0 | BJ34: 0 | BK34: 0 | BL34: 0 | BM34: 0 | BN34: 0 | BO34: 0 | BR34: 0 | BS34: 0 | BT34: 0 | BV34: 0 | BZ34: =SUM(T34:BY34) -> 101 | CA34: B | CC34: =SUM(BG34:BV34,AE34:AW34,AY34:BE34,T34:AC34)/BZ34 -> 0.079207921 | CD34: =BZ34-SUM(BF34,AX34,AW34,AD34,W34) -> 7 | CE34: =SUM(AX34:BV34) -> 91 | CF34: =SUM(BG34:BV34,AY34:BE34) -> 1 | CG34: =CF34/CE34 -> 0.010989011 | CH34: Memphis
A35: 11-P-2 | B35: Bradley | C35: AR | D35: 3CT0007 | E35: Crittenden | F35: 406 | G35: 08N/09E/17 | H35: =LOOKUP(A35,'[1]AMASDA DATA'!B27:B203,'[1]AMASDA DATA'!H27:H203) -> 3910900 | I35: =LOOKUP(A35,'[1]AMASDA DATA'!B27:B203,'[1]AMASDA DATA'!I27:I203) -> 758280 | J35: 15 | L35: Mounds and village site (mostly destroyed) | M35: Phillips | N35: 14724 | O35: map | T35: 0 | U35: 0 | V35: 0 | W35: 0 | Y35: 0 | Z35: 0 | AA35: 0 | AC35: 0 | AD35: 43 | AE35: 14 | AF35: 0 | AG35: 0 | AH35: 0 | AJ35: 0 | AL35: 0 | AM35: 0 | AN35: 0 | AP35: 0 | AQ35: 0 | AR35: 0 | AS35: 0 | AT35: 0 | AV35: 0 | AW35: 0 | AX35: 225 | AY35: 5 | AZ35: 1 | BA35: 0 | BB35: 0 | BC35: 0 | BD35: 0 | BE35: 0 | BF35: 222 | BG35: 1 | BH35: 0 | BI35: 0 | BJ35: 0 | BK35: 0 | BL35: 2 | BM35: 0 | BN35: 0 | BO35: 1 | BR35: 0 | BS35: 0 | BT35: 0 | BV35: 0 | BZ35: =SUM(T35:BY35) -> 514 | CA35: B | CC35: =SUM(BG35:BV35,AE35:AW35,AY35:BE35,T35:AC35)/BZ35 -> 0.046692607 | CD35: =BZ35-SUM(BF35,AX35,AW35,AD35,W35) -> 24 | CE35: =SUM(AX35:BV35) -> 457 | CF35: =SUM(BG35:BV35,AY35:BE35) -> 10 | CG35: =CF35/CE35 -> 0.021881838 | CH35: Memphis
A36: 11-P-2/A | B36: Bradley | C36: AR | D36: 3CT0007 | E36: Crittenden | F36: 406 | G36: 08N/09E/17 | H36: 3910900 | I36: =LOOKUP(A36,'[1]AMASDA DATA'!B28:B204,'[1]AMASDA DATA'!I28:I204) -> 758280 | J36: 15 | L36: Mounds and village site (mostly destroyed) | M36: Phillips | N36: 14724 | O36: map | T36: 0 | U36: 0 | V36: 0 | W36: 0 | Y36: 0 | Z36: 0 | AA36: 1 | AC36: 0 | AD36: 3 | AE36: 3 | AF36: 0 | AG36: 4 | AH36: 0 | AJ36: 0 | AL36: 0 | AM36: 0 | AN36: 0 | AP36: 0 | AQ36: 0 | AR36: 0 | AS36: 0 | AT36: 0 | AV36: 0 | AW36: 0 | AX36: 0 | AY36: 0 | AZ36: 0 | BA36: 0 | BB36: 0 | BC36: 0 | BD36: 0 | BE36: 0 | BF36: 0 | BG36: 0 | BH36: 0 | BI36: 0 | BJ36: 0 | BK36: 0 | BL36: 0 | BM36: 0 | BN36: 0 | BO36: 0 | BR36: 0 | BS36: 0 | BT36: 0 | BV36: 0 | BZ36: =SUM(T36:BY36) -> 11 | CA36: ?? | CC36: =SUM(BG36:BV36,AE36:AW36,AY36:BE36,T36:AC36)/BZ36 -> 0.72727273 | CD36: =BZ36-SUM(BF36,AX36,AW36,AD36,W36) -> 8 | CE36: =SUM(AX36:BV36) -> 0 | CF36: =SUM(BG36:BV36,AY36:BE36) -> 0 | CG36: =CF36/CE36 -> #DIV/0! | CH36: Memphis
A37: 11-P-3 | B37: Golightly | C37: AR | D37: 3CT0019 | E37: Crittenden | F37: 406 | G37: 09N/08E/26 | H37: =H39+(0.8*1.6+1000) -> 3918541.3 | I37: =I39-(2*1.6*1000) -> 753900 | J37: 15 | L37: Two mounds and village site | M37: Phillips | N37: 14721 | O37: map | T37: 0 | U37: 0 | V37: 0 | W37: 0 | Y37: 0 | Z37: 0 | AA37: 0 | AC37: 0 | AD37: 26 | AE37: 6 | AF37: 1 | AG37: 0 | AH37: 0 | AJ37: 0 | AL37: 0 | AM37: 0 | AN37: 0 | AP37: 0 | AQ37: 0 | AR37: 0 | AS37: 0 | AT37: 0 | AV37: 0 | AW37: 0 | AX37: 112 | AY37: 0 | AZ37: 0 | BA37: 0 | BB37: 0 | BC37: 0 | BD37: 0 | BE37: 0 | BF37: 94 | BG37: 0 | BH37: 0 | BI37: 0 | BJ37: 0 | BK37: 0 | BL37: 0 | BM37: 0 | BN37: 0 | BO37: 0 | BR37: 0 | BS37: 0 | BT37: 0 | BV37: 0 | BZ37: =SUM(T37:BY37) -> 239 | CA37: B | CC37: =SUM(BG37:BV37,AE37:AW37,AY37:BE37,T37:AC37)/BZ37 -> 0.029288703 | CD37: =BZ37-SUM(BF37,AX37,AW37,AD37,W37) -> 7 | CE37: =SUM(AX37:BV37) -> 206 | CF37: =SUM(BG37:BV37,AY37:BE37) -> 0 | CG37: =CF37/CE37 -> 0 | CH37: Memphis
A38: 11-P-4 | B38: Pacific | C38: AR | D38: 3CT0026 | E38: Crittenden | F38: 279 | G38: 09N/08E/23 | H38: =H39-(0.2*1.6*1000) -> 3917220 | I38: =I39-(2.2*1.6*1000) -> 753580 | J38: 15 | L38: Three small mounds | M38: Phillips | N38: 14725 | T38: 0 | U38: 0 | V38: 0 | W38: 0 | Y38: 0 | Z38: 0 | AA38: 0 | AC38: 0 | AD38: 0 | AE38: 0 | AF38: 0 | AG38: 0 | AH38: 0 | AJ38: 0 | AL38: 0 | AM38: 0 | AN38: 0 | AP38: 0 | AQ38: 0 | AR38: 0 | AS38: 0 | AT38: 0 | AV38: 0 | AW38: 0 | AX38: 2 | AY38: 0 | AZ38: 0 | BA38: 0 | BB38: 0 | BC38: 0 | BD38: 0 | BE38: 0 | BF38: 4 | BG38: 0 | BH38: 0 | BI38: 0 | BJ38: 0 | BK38: 0 | BL38: 0 | BM38: 0 | BN38: 0 | BO38: 0 | BR38: 0 | BS38: 0 | BT38: 0 | BV38: 0 | BZ38: =SUM(T38:BY38) -> 6 | CA38: ?? | CC38: =SUM(BG38:BV38,AE38:AW38,AY38:BE38,T38:AC38)/BZ38 -> 0 | CD38: =BZ38-SUM(BF38,AX38,AW38,AD38,W38) -> 0 | CE38: =SUM(AX38:BV38) -> 6 | CF38: =SUM(BG38:BV38,AY38:BE38) -> 0 | CG38: =CF38/CE38 -> 0 | CH38: Memphis
A39: 11-P-5 | B39: Lambethville | C39: AR | D39: 3CT0027 | E39: Crittenden | F39: 406 | G39: 09N/09E/30 | H39: 3917540 | I39: 757100 | J39: 15 | L39: Three small mounds | M39: Phillips | N39: 14725 | O39: map | T39: 0 | U39: 0 | V39: 0 | W39: 0 | Y39: 0 | Z39: 0 | AA39: 0 | AC39: 0 | AD39: 10 | AE39: 0 | AF39: 0 | AG39: 0 | AH39: 0 | AJ39: 0 | AL39: 0 | AM39: 0 | AN39: 0 | AP39: 0 | AQ39: 0 | AR39: 0 | AS39: 0 | AT39: 0 | AV39: 0 | AW39: 0 | AX39: 0 | AY39: 0 | AZ39: 0 | BA39: 0 | BB39: 0 | BC39: 0 | BD39: 0 | BE39: 0 | BF39: 1 | BG39: 0 | BH39: 0 | BI39: 0 | BJ39: 0 | BK39: 0 | BL39: 0 | BM39: 0 | BN39: 0 | BO39: 0 | BR39: 0 | BS39: 0 | BT39: 0 | BV39: 0 | BZ39: =SUM(T39:BY39) -> 11 | CA39: ?? | CC39: =SUM(BG39:BV39,AE39:AW39,AY39:BE39,T39:AC39)/BZ39 -> 0 | CD39: =BZ39-SUM(BF39,AX39,AW39,AD39,W39) -> 0 | CE39: =SUM(AX39:BV39) -> 1 | CF39: =SUM(BG39:BV39,AY39:BE39) -> 0 | CG39: =CF39/CE39 -> 0 | CH39: Memphis
A40: 12-N-10 | B40: DeRossitt's Place | C40: AR | D40: 3SF0027 | E40: St Francis | F40: 459 | G40: 05N/04E/4 | H40: 3883280 | I40: 711650 | J40: 15 | L40: Mound and village site | M40: Ford, Griffin, Phillips | N40: 14703 | T40: 0 | U40: 0 | V40: 0 | W40: 0 | Y40: 0 | Z40: 0 | AA40: 0 | AC40: 0 | AD40: 518 | AE40: 146 | AF40: 0 | AG40: 0 | AH40: 16 | AJ40: 0 | AL40: 0 | AM40: 0 | AN40: 0 | AP40: 0 | AQ40: 3 | AR40: 0 | AS40: 0 | AT40: 0 | AV40: 0 | AW40: 1 | AX40: 18 | AY40: 0 | AZ40: 0 | BA40: 0 | BB40: 0 | BC40: 0 | BD40: 0 | BE40: 0 | BF40: 0 | BG40: 0 | BH40: 0 | BI40: 0 | BJ40: 0 | BK40: 0 | BL40: 0 | BM40: 0 | BN40: 0 | BO40: 0 | BR40: 0 | BS40: 0 | BT40: 0 | BV40: 0 | BZ40: =SUM(T40:BY40) -> 702 | CA40: D | CC40: =SUM(BG40:BV40,AE40:AW40,AY40:BE40,T40:AC40)/BZ40 -> 0.23646724 | CD40: =BZ40-SUM(BF40,AX40,AW40,AD40,W40) -> 165 | CE40: =SUM(AX40:BV40) -> 18 | CF40: =SUM(BG40:BV40,AY40:BE40) -> 0 | CG40: =CF40/CE40 -> 0 | CH40: St. Francis
...

Sheet MainfortXY
A1: Site_Name | B1: Latitude | C1: Longitude
A2: Porter | B2: 35.698 | C2: -89.779
A3: 40LA007 | B3: 35.83851 | C3: -89.623299
A4: Hatchie | B4: 35.536257 | C4: -89.869834
A5: Bishop | B5: 35.633 | C5: -89.664
A6: Richardsons_Landing | B6: 35.502 | C6: -89.948
A7: Wilder | B7: 35.453 | C7: -89.973
A8: 40TP026 | B8: 35.496564 | C8: -89.970203
A9: Jones_Bayou | B9: 35.719 | C9: -89.772
A10: 40LA017 | B10: 35.733 | C10: 35.733
A11: Fullen | B11: 35.704 | C11: -89.862
A12: Jeter | B12: 35.269 | C12: -90.062
A13: Rast | B13: 35.391 | C13: -89.993
... A57: Otto Sharpe | B57: 36.484 | C57: -89.379

Sheet Spatial Data
A1: Name | B1: latitude | C1: longitude
A2: Armorel | B2: 35.91 | C2: -89.792
A3: Barton Ranch | B3: 35.377 | C3: -90.389
A4: Beck | B4: 34.916 | C4: -90.156
A5: Bell | B5: 35.529 | C5: -90.115
A6: Belle Meade | B6: 34.921 | C6: -90.392
A7: Berry | B7: 36.045 | C7: -89.755
A8: Big Eddy | B8: 35.12 | C8: -90.696
A9: Bishop | B9: 35.633 | C9: -89.664
A10: Cagle Lake | B10: 36.111 | C10: -89.702
A11: Campbell | B11: 36.04 | C11: -89.794
A12: Carson Lake | B12: 35.597 | C12: -90.047
A13: CastileLndg | B13: 34.977 | C13: -90.678
... A708: Zeebree | B708: 36.495321 | C708: -90.155658

Sheet pfgXY
A1: Assemblage | B1: Northing | C1: Easting | D1: Zone | E1: Latitude | F1: Longitude
A2: 10-P-1 | B2: 3943300 | C2: 767520 | D2: 15 | E2: -90.047131 | F2: 35.597305
A3: 10-P-2 | B3: 3935520 | C3: 761580 | D3: 15 | E3: -90.115135 | F3: 35.528834
A4: 10-P-3 | B4: 3934120 | C4: 760410 | D4: 15 | E4: -90.128473 | F4: 35.516534
A5: 10-P-4 | B5: 3936400 | C5: 762620 | D5: 15 | E5: -90.103393 | F5: 35.536483
A6: 10-Q-1 | B6: 3943700 | C6: 773800 | D6: 15 | E6: -89.977762 | F6: 35.599189
A7: 10-Q-3 | B7: 3940400 | C7: 773550 | D7: 15 | E7: -89.981635 | F7: 35.569545
A8: 11-N-1 | B8: 3906400 | C8: 722250 | D8: 15 | E8: -90.556439 | F8: 35.276098
A9: 11-N-10 | B9: 3904500 | C9: 710900 | D9: 15 | E9: -90.681623 | F9: 35.261436
A10: 11-N-11 | B10: 3910400 | C10: 719500 | D10: 15 | E10: -90.58558 | F10: 35.312741
A11: 11-N-12 | B11: 3924500 | C11: 724720 | D11: 15 | E11: -90.52433 | F11: 35.4386
A12: 11-N-13 | B12: 3909500 | C12: 719950 | D12: 15 | E12: -90.580876 | F12: 35.304534
A13: 11-N-14 | B13: 3918950 | C13: 723125 | D13: 15 | E13: -90.543406 | F13: 35.388962
... A138: Holden_Lake | B138: 3902950 | C138: 734391 | D138: 15 | E138: -90.424055 | F138: 35.242252

Sheet pfg-cpl-mainfortXY
A1: Assemblages | B1: Latitude | C1: Longitude
A2: 40LA007 | B2: =VLOOKUP(A2,MainfortXY!A:C,2,FALSE) -> 35.83851 | C2: =VLOOKUP(A2,MainfortXY!A:C,3,FALSE) -> -89.623299
A3: 40TP026 | B3: =VLOOKUP(A3,MainfortXY!A:C,2,FALSE) -> 35.496564 | C3: =VLOOKUP(A3,MainfortXY!A:C,3,FALSE) -> -89.970203
A4: Barton_Ranch | B4: 35.377167 | C4: -90.389406
A5: Beck | B5: =VLOOKUP(A5,MainfortXY!A:C,2,FALSE) -> 34.916 | C5: =VLOOKUP(A5,MainfortXY!A:C,3,FALSE) -> -90.156
A6: Belle_Meade | B6: =VLOOKUP(A6,MainfortXY!A:C,2,FALSE) -> 34.921 | C6: =VLOOKUP(A6,MainfortXY!A:C,3,FALSE) -> -90.445492
A7: Big_Eddy | B7: =VLOOKUP(A7,MainfortXY!A:C,2,FALSE) -> 35.12 | C7: =VLOOKUP(A7,MainfortXY!A:C,3,FALSE) -> -90.696
A8: Bishop | B8: =VLOOKUP(A8,MainfortXY!A:C,2,FALSE) -> 35.633 | C8: =VLOOKUP(A8,MainfortXY!A:C,3,FALSE) -> -89.664
A9: Carson_Lake | B9: =VLOOKUP(A9,MainfortXY!A:C,2,FALSE) -> 35.597 | C9: =VLOOKUP(A9,MainfortXY!A:C,3,FALSE) -> -90.047
A10: Castile_Landing | B10: =VLOOKUP(A10,MainfortXY!A:C,2,FALSE) -> 34.975773 | C10: =VLOOKUP(A10,MainfortXY!A:C,3,FALSE) -> -90.677659
A11: Cheatham | B11: =VLOOKUP(A11,MainfortXY!A:C,2,FALSE) -> 34.964 | C11: =VLOOKUP(A11,MainfortXY!A:C,3,FALSE) -> -90.176
A12: Chuccalissa | B12: =VLOOKUP(A12,MainfortXY!A:C,2,FALSE) -> 35.055 | C12: =VLOOKUP(A12,MainfortXY!A:C,3,FALSE) -> -90.122
A13: Clay_Hill | B13: =VLOOKUP(A13,MainfortXY!A:C,2,FALSE) -> 34.877 | C13: =VLOOKUP(A13,MainfortXY!A:C,3,FALSE) -> -90.724195
A14: Commerce | B14: =VLOOKUP(A14,MainfortXY!A:C,2,FALSE) -> 34.816084 | C14: =VLOOKUP(A14,MainfortXY!A:C,3,FALSE) -> -90.382255
A15: Connor | B15: =VLOOKUP(A15,MainfortXY!A:C,2,FALSE) -> 34.856804 | C15: =VLOOKUP(A15,MainfortXY!A:C,3,FALSE) -> -90.688664
A16: Cramor_Place | B16: 35.004579 | C16: -90.485663
A17: Cummins | B17: =VLOOKUP(A17,MainfortXY!A:C,2,FALSE) -> 35.617462 | C17: =VLOOKUP(A17,MainfortXY!A:C,3,FALSE) -> -90.633192
A18: Davis | B18: =VLOOKUP(A18,MainfortXY!A:C,2,FALSE) -> 34.863687 | C18: =VLOOKUP(A18,MainfortXY!A:C,3,FALSE) -> -90.514832
A19: Dundee | B19: =VLOOKUP(A19,MainfortXY!A:C,2,FALSE) -> 34.520896 | C19: =VLOOKUP(A19,MainfortXY!A:C,3,FALSE) -> -90.460518
A20: Fortune | B20: =VLOOKUP(A20,MainfortXY!A:C,2,FALSE) -> 35.413527 | C20: =VLOOKUP(A20,MainfortXY!A:C,3,FALSE) -> -90.545688
A21: Fullen | B21: =VLOOKUP(A21,MainfortXY!A:C,2,FALSE) -> 35.704 | C21: =VLOOKUP(A21,MainfortXY!A:C,3,FALSE) -> -89.862
A22: Grant | B22: =VLOOKUP(A22,MainfortXY!A:C,2,FALSE) -> 34.756387 | C22: =VLOOKUP(A22,MainfortXY!A:C,3,FALSE) -> -90.61636
A23: Graves_Lake | B23: =VLOOKUP(A23,MainfortXY!A:C,2,FALSE) -> 35.597 | C23: =VLOOKUP(A23,MainfortXY!A:C,3,FALSE) -> -89.886
A24: Hatchie | B24: =VLOOKUP(A24,MainfortXY!A:C,2,FALSE) -> 35.536257 | C24: =VLOOKUP(A24,MainfortXY!A:C,3,FALSE) -> -89.869834
A25: Holden_Lake | B25: 35.242252 | C25: -90.424055
A26: Hollywood | B26: =VLOOKUP(A26,MainfortXY!A:C,2,FALSE) -> 34.77552 | C26: =VLOOKUP(A26,MainfortXY!A:C,3,FALSE) -> -90.370603
A27: Irby | B27: =VLOOKUP(A27,MainfortXY!A:C,2,FALSE) -> 34.916011 | C27: =VLOOKUP(A27,MainfortXY!A:C,3,FALSE) -> -90.156281
A28: Jeter | B28: =VLOOKUP(A28,MainfortXY!A:C,2,FALSE) -> 35.269 | C28: =VLOOKUP(A28,MainfortXY!A:C,3,FALSE) -> -90.062
A29: Jones_Bayou | B29: =VLOOKUP(A29,MainfortXY!A:C,2,FALSE) -> 35.719 | C29: =VLOOKUP(A29,MainfortXY!A:C,3,FALSE) -> -89.772
A30: Kent_Place | B30: 34.81 | C30: -90.531
A31: Lake_Cormorant | B31: =VLOOKUP(A31,MainfortXY!A:C,2,FALSE) -> 34.91882 | C31: =VLOOKUP(A31,MainfortXY!A:C,3,FALSE) -> -90.19999
A32: Mound_Place | B32: =VLOOKUP(A32,MainfortXY!A:C,2,FALSE) -> 35.079 | C32: =VLOOKUP(A32,MainfortXY!A:C,3,FALSE) -> -90.239
A33: Neeleys_Ferry | B33: =VLOOKUP(A33,MainfortXY!A:C,2,FALSE) -> 35.339786 | C33: =VLOOKUP(A33,MainfortXY!A:C,3,FALSE) -> -90.540991
A34: Nickel | B34: =VLOOKUP(A34,MainfortXY!A:C,2,FALSE) -> 34.961219 | C34: =VLOOKUP(A34,MainfortXY!A:C,3,FALSE) -> -90.542834
A35: Norfolk | B35: =VLOOKUP(A35,MainfortXY!A:C,2,FALSE) -> 34.94801 | C35: =VLOOKUP(A35,MainfortXY!A:C,3,FALSE) -> -90.233142
A36: Notgrass | B36: =VLOOKUP(A36,MainfortXY!A:C,2,FALSE) -> 35.536483 | C36: =VLOOKUP(A36,MainfortXY!A:C,3,FALSE) -> -90.103393
A37: Parchman | B37: =VLOOKUP(A37,MainfortXY!A:C,2,FALSE) -> 34.358595 | C37: =VLOOKUP(A37,MainfortXY!A:C,3,FALSE) -> -90.565707
A38: Parkin | B38: =VLOOKUP(A38,MainfortXY!A:C,2,FALSE) -> 35.276 | C38: =VLOOKUP(A38,MainfortXY!A:C,3,FALSE) -> -90.556
A39: Porter | B39: =VLOOKUP(A39,MainfortXY!A:C,2,FALSE) -> 35.698 | C39: =VLOOKUP(A39,MainfortXY!A:C,3,FALSE) -> -89.779
A40: Pouncey | B40: =VLOOKUP(A40,MainfortXY!A:C,2,FALSE) -> 35.024356 | C40: =VLOOKUP(A40,MainfortXY!A:C,3,FALSE) -> -90.359236
...
